Workbook

Sheet final sheet
A1: IMC/JW/25090028,IMC/JW/25090029,IMC/JW/25090030,IMC/JW/25090031
C3: Sum of Converted Qty | E3: Column Labels
C4: Row Labels | E4: IMC/JW/25090028 | F4: IMC/JW/25090029 | G4: IMC/JW/25090030 | H4: IMC/JW/25090031 | I4: (blank) | J4: Grand Total | K4: PHY QTY | L4: E & S | N4: KEM PART CODE | O4: SR.NO
A5: IN | B5: 1 | C5: 01S0000K21-00 | D5: =+VLOOKUP(C5,Sheet1!K:M,3,) -> RES-MO-SMD 0R-5%-0402-63mW-55-155℃-TC400 | E5: 30000 | J5: 30000 | K5: =10000*3 -> 30000 | L5: =+K5-J5 -> 0 | N5: =+CONCATENATE(A5,C5) -> IN01S0000K21-00 | O5: 1 | Q5: =+VLOOKUP(N5,Sheet2!A:A,1,) -> IN01S0000K21-00
A6: IN | B6: 2 | C6: 01S1000110-00 | D6: =+VLOOKUP(C6,Sheet1!K:M,3,) -> RES-MO-SMD 100R-1%-1206-250mW-55-155℃-TC100 | E6: 5000 | J6: 5000 | K6: =5000*1 -> 5000 | L6: =+K6-J6 -> 0 | N6: =+CONCATENATE(A6,C6) -> IN01S1000110-00 | O6: 2 | Q6: =+VLOOKUP(N6,Sheet2!A:A,1,) -> IN01S1000110-00
A7: IN | B7: 3 | C7: 01S1001310-00 | D7: =+VLOOKUP(C7,Sheet1!K:M,3,) -> RES-MO-SMD 1K-1%-0603-100mW-55-155℃-TC100 | E7: 15000 | J7: 15000 | K7: =5000*3 -> 15000 | L7: =+K7-J7 -> 0 | N7: =+CONCATENATE(A7,C7) -> IN01S1001310-00 | O7: 3 | Q7: =+VLOOKUP(N7,Sheet2!A:A,1,) -> IN01S1001310-00
A8: IN | B8: 4 | C8: 01S1002110-00 | D8: =+VLOOKUP(C8,Sheet1!K:M,3,) -> RES-MO-SMD 10K-1%-1206-250mW-55-155℃-TC100 | E8: 10000 | J8: 10000 | K8: =5000*2 -> 10000 | L8: =+K8-J8 -> 0 | N8: =+CONCATENATE(A8,C8) -> IN01S1002110-00 | O8: 4 | Q8: =+VLOOKUP(N8,Sheet2!A:A,1,) -> IN01S1002110-00
A9: IN | B9: 5 | C9: 01S1002310-00 | D9: =+VLOOKUP(C9,Sheet1!K:M,3,) -> RES-MO-SMD 10K-1%-0603-100mW-55-155℃-TC100 | E9: 30000 | J9: 30000 | K9: =5000*6 -> 30000 | L9: =+K9-J9 -> 0 | N9: =+CONCATENATE(A9,C9) -> IN01S1002310-00 | O9: 5 | Q9: =+VLOOKUP(N9,Sheet2!A:A,1,) -> IN01S1002310-00
A10: IN | B10: 6 | C10: 01S1002340-00 | D10: =+VLOOKUP(C10,Sheet1!K:M,3,) -> RES-MT-SMD 10K-0.1%-0603-100mW-55-155℃-TC50 | F10: 5000 | J10: 5000 | K10: =5000*1 -> 5000 | L10: =+K10-J10 -> 0 | N10: =+CONCATENATE(A10,C10) -> IN01S1002340-00 | O10: 6 | Q10: =+VLOOKUP(N10,Sheet2!A:A,1,) -> IN01S1002340-00
A11: IN | B11: 7 | C11: 01S1003310-00 | D11: =+VLOOKUP(C11,Sheet1!K:M,3,) -> RES-MO-SMD 100K-1%-0603-100mW-55-155℃-TC100 | E11: 20000 | J11: 20000 | K11: =5000*4 -> 20000 | L11: =+K11-J11 -> 0 | N11: =+CONCATENATE(A11,C11) -> IN01S1003310-00 | O11: 7 | Q11: =+VLOOKUP(N11,Sheet2!A:A,1,) -> IN01S1003310-00
A12: IN | B12: 8 | C12: 01S1003311-13 | D12: =+VLOOKUP(C12,Sheet1!K:M,3,) -> RES-NTC-SMD 100K-1%-84V-4050K-2.5A-0603 | E12: 8000 | J12: 8000 | K12: =4000*2 -> 8000 | L12: =+K12-J12 -> 0 | N12: =+CONCATENATE(A12,C12) -> IN01S1003311-13 | O12: 8 | Q12: =+VLOOKUP(N12,Sheet2!A:A,1,) -> IN01S1003311-13
A13: IN | B13: 9 | C13: 01S1004310-00 | D13: =+VLOOKUP(C13,Sheet1!K:M,3,) -> RES-MO-SMD 1M-1%-0603-100mW-55-155℃-TC100 | G13: 10000 | J13: 10000 | K13: =5000*2 -> 10000 | L13: =+K13-J13 -> 0 | N13: =+CONCATENATE(A13,C13) -> IN01S1004310-00 | O13: 9 | Q13: =+VLOOKUP(N13,Sheet2!A:A,1,) -> IN01S1004310-00
A14: IN | B14: 10 | C14: 01S1007121-02 | D14: =+VLOOKUP(C14,Sheet1!K:M,3,) -> RES-Anti Surge-SMD 10R-5%-1206-250mW-55-155℃-TC400 | G14: 10000 | J14: 10000 | K14: =5000*2 -> 10000 | L14: =+K14-J14 -> 0 | N14: =+CONCATENATE(A14,C14) -> IN01S1007121-02 | O14: 10 | Q14: =+VLOOKUP(N14,Sheet2!A:A,1,) -> IN01S1007121-02
A15: IN | B15: 11 | C15: 01S1101310-00 | D15: =+VLOOKUP(C15,Sheet1!K:M,3,) -> RES-MO-SMD 1K1-1%-0603-100mW-55-155℃-TC100 | G15: 10000 | J15: 10000 | K15: =5000*2 -> 10000 | L15: =+K15-J15 -> 0 | N15: =+CONCATENATE(A15,C15) -> IN01S1101310-00 | O15: 11 | Q15: =+VLOOKUP(N15,Sheet2!A:A,1,) -> IN01S1101310-00
A16: IN | B16: 12 | C16: 01S1103110-00 | D16: =+VLOOKUP(C16,Sheet1!K:M,3,) -> RES-MO-SMD 110K-1%-1206-250mW-55-155℃-TC100 | G16: 15000 | J16: 15000 | K16: =5000*3 -> 15000 | L16: =+K16-J16 -> 0 | N16: =+CONCATENATE(A16,C16) -> IN01S1103110-00 | O16: 12 | Q16: =+VLOOKUP(N16,Sheet2!A:A,1,) -> IN01S1103110-00
A17: IN | B17: 13 | C17: 01S1204111-00 | D17: =+VLOOKUP(C17,Sheet1!K:M,3,) -> RES-MO-SMD 1M2-1%-1206-250mW-55-155℃-TC250 | F17: 10000 | J17: 10000 | K17: =5000*2 -> 10000 | L17: =+K17-J17 -> 0 | N17: =+CONCATENATE(A17,C17) -> IN01S1204111-00 | O17: 13 | Q17: =+VLOOKUP(N17,Sheet2!A:A,1,) -> IN01S1204111-00
A18: IN | B18: 14 | C18: 01S1303110-00 | D18: =+VLOOKUP(C18,Sheet1!K:M,3,) -> RES-MO-SMD 130K-1%-1206-250mW-55-155℃-TC100 | G18: 120000 | J18: 120000 | K18: =5000*20+5000*4 -> 120000 | L18: =+K18-J18 -> 0 | N18: =+CONCATENATE(A18,C18) -> IN01S1303110-00 | O18: 14 | Q18: =+VLOOKUP(N18,Sheet2!A:A,1,) -> IN01S1303110-00
A19: IN | B19: 15 | C19: 01S1501310-00 | D19: =+VLOOKUP(C19,Sheet1!K:M,3,) -> RES-MO-SMD 1K5-1%-0603-100mW-55-155℃-TC100 | G19: 5000 | J19: 5000 | K19: =5000*1 -> 5000 | L19: =+K19-J19 -> 0 | N19: =+CONCATENATE(A19,C19) -> IN01S1501310-00 | O19: 15 | Q19: =+VLOOKUP(N19,Sheet2!A:A,1,) -> IN01S1501310-00
A20: IN | B20: 16 | C20: 01S1502110-00 | D20: =+VLOOKUP(C20,Sheet1!K:M,3,) -> RES-MO-SMD 15K-1%-1206-250mW-55-155℃-TC100 | H20: 20000 | J20: 20000 | K20: =5000*4 -> 20000 | L20: =+K20-J20 -> 0 | N20: =+CONCATENATE(A20,C20) -> IN01S1502110-00 | O20: 16 | Q20: =+VLOOKUP(N20,Sheet2!A:A,1,) -> IN01S1502110-00
A21: IN | B21: 17 | C21: 01S1502310-00 | D21: =+VLOOKUP(C21,Sheet1!K:M,3,) -> RES-MO-SMD 15K-1%-0603-100mW-55-155℃-TC100 | G21: 15000 | J21: 15000 | K21: =5000*3 -> 15000 | L21: =+K21-J21 -> 0 | N21: =+CONCATENATE(A21,C21) -> IN01S1502310-00 | O21: 17 | Q21: =+VLOOKUP(N21,Sheet2!A:A,1,) -> IN01S1502310-00
A22: IN | B22: 18 | C22: 01S1503110-00 | D22: =+VLOOKUP(C22,Sheet1!K:M,3,) -> RES-MO-SMD 150K-1%-1206-250mW-55-155℃-TC100 | H22: 25000 | J22: 25000 | K22: =5000*5 -> 25000 | L22: =+K22-J22 -> 0 | N22: =+CONCATENATE(A22,C22) -> IN01S1503110-00 | O22: 18 | Q22: =+VLOOKUP(N22,Sheet2!A:A,1,) -> IN01S1503110-00
A23: IN | B23: 19 | C23: 01S1503210-00 | D23: =+VLOOKUP(C23,Sheet1!K:M,3,) -> RES-MO-SMD 150K-1%-0805-125mW-55-155℃-TC100 | F23: 5000 | J23: 5000 | K23: =5000*1 -> 5000 | L23: =+K23-J23 -> 0 | N23: =+CONCATENATE(A23,C23) -> IN01S1503210-00 | O23: 19 | Q23: =+VLOOKUP(N23,Sheet2!A:A,1,) -> IN01S1503210-00
A24: IN | B24: 20 | C24: 01S1503310-00 | D24: =+VLOOKUP(C24,Sheet1!K:M,3,) -> RES-MO-SMD 150K-1%-0603-100mW-55-155℃-TC100 | H24: 15000 | J24: 15000 | K24: =5000*3 -> 15000 | L24: =+K24-J24 -> 0 | N24: =+CONCATENATE(A24,C24) -> IN01S1503310-00 | O24: 20 | Q24: =+VLOOKUP(N24,Sheet2!A:A,1,) -> IN01S1503310-00
A25: IN | B25: 21 | C25: 01S1603310-00 | D25: =+VLOOKUP(C25,Sheet1!K:M,3,) -> RES-MO-SMD 160K-1%-0603-100mW-55-155℃-TC100 | F25: 10000 | J25: 10000 | K25: =5000*2 -> 10000 | L25: =+K25-J25 -> 0 | N25: =+CONCATENATE(A25,C25) -> IN01S1603310-00 | O25: 21 | Q25: =+VLOOKUP(N25,Sheet2!A:A,1,) -> IN01S1603310-00
A26: IN | B26: 22 | C26: 01S1802310-00 | D26: =+VLOOKUP(C26,Sheet1!K:M,3,) -> RES-MO-SMD 18K-1%-0603-100mW-55-155℃-TC100 | F26: 30000 | J26: 30000 | K26: =5000*6 -> 30000 | L26: =+K26-J26 -> 0 | N26: =+CONCATENATE(A26,C26) -> IN01S1802310-00 | O26: 22 | Q26: =+VLOOKUP(N26,Sheet2!A:A,1,) -> IN01S1802310-00
A27: IN | B27: 23 | C27: 01S2001310-00 | D27: =+VLOOKUP(C27,Sheet1!K:M,3,) -> RES-MO-SMD 2K-1%-0603-100mW-55-155℃-TC100 | F27: 10000 | J27: 10000 | K27: =5000*2 -> 10000 | L27: =+K27-J27 -> 0 | N27: =+CONCATENATE(A27,C27) -> IN01S2001310-00 | O27: 23 | Q27: =+VLOOKUP(N27,Sheet2!A:A,1,) -> IN01S2001310-00
A28: IN | B28: 24 | C28: 01S2002310-00 | D28: =+VLOOKUP(C28,Sheet1!K:M,3,) -> RES-MO-SMD 20K-1%-0603-100mW-55-155℃-TC100 | H28: 15000 | J28: 15000 | K28: =5000*3 -> 15000 | L28: =+K28-J28 -> 0 | N28: =+CONCATENATE(A28,C28) -> IN01S2002310-00 | O28: 24 | Q28: =+VLOOKUP(N28,Sheet2!A:A,1,) -> IN01S2002310-00
A29: IN | B29: 25 | C29: 01S2003310-00 | D29: =+VLOOKUP(C29,Sheet1!K:M,3,) -> RES-MO-SMD 200K-1%-0603-100mW-55-155℃-TC100 | G29: 15000 | J29: 15000 | K29: =5000*3 -> 15000 | L29: =+K29-J29 -> 0 | N29: =+CONCATENATE(A29,C29) -> IN01S2003310-00 | O29: 25 | Q29: =+VLOOKUP(N29,Sheet2!A:A,1,) -> IN01S2003310-00
A30: IN | B30: 26 | C30: 01S2004310-00 | D30: =+VLOOKUP(C30,Sheet1!K:M,3,) -> RES-MO-SMD 2M-1%-0603-100mW-55-155℃-TC100 | G30: 10000 | J30: 10000 | K30: =5000*2 -> 10000 | L30: =+K30-J30 -> 0 | N30: =+CONCATENATE(A30,C30) -> IN01S2004310-00 | O30: 26 | Q30: =+VLOOKUP(N30,Sheet2!A:A,1,) -> IN01S2004310-00
A31: IN | B31: 27 | C31: 01S2007121-02 | D31: =+VLOOKUP(C31,Sheet1!K:M,3,) -> RES-Anti Surge-SMD 20R-5%-1206-250mW-55-155℃-TC200 | F31: 40000 | J31: 40000 | K31: =5000*8 -> 40000 | L31: =+K31-J31 -> 0 | N31: =+CONCATENATE(A31,C31) -> IN01S2007121-02 | O31: 27 | Q31: =+VLOOKUP(N31,Sheet2!A:A,1,) -> IN01S2007121-02
A32: IN | B32: 28 | C32: 01S2201310-00 | D32: =+VLOOKUP(C32,Sheet1!K:M,3,) -> RES-MO-SMD 2K2-1%-0603-100mW-55-155℃-TC100 | G32: 5000 | J32: 5000 | K32: =5000*1 -> 5000 | L32: =+K32-J32 -> 0 | N32: =+CONCATENATE(A32,C32) -> IN01S2201310-00 | O32: 28 | Q32: =+VLOOKUP(N32,Sheet2!A:A,1,) -> IN01S2201310-00
A33: IN | B33: 29 | C33: 01S2202310-00 | D33: =+VLOOKUP(C33,Sheet1!K:M,3,) -> RES-MO-SMD 22K-1%-0603-100mW-55-155℃-TC100 | G33: 10000 | J33: 10000 | K33: =5000*2 -> 10000 | L33: =+K33-J33 -> 0 | N33: =+CONCATENATE(A33,C33) -> IN01S2202310-00 | O33: 29 | Q33: =+VLOOKUP(N33,Sheet2!A:A,1,) -> IN01S2202310-00
A34: IN | B34: 30 | C34: 01S2203110-00 | D34: =+VLOOKUP(C34,Sheet1!K:M,3,) -> RES-MO-SMD 220K-1%-1206-250mW-55-155℃-TC100 | H34: 25000 | J34: 25000 | K34: =5000*5 -> 25000 | L34: =+K34-J34 -> 0 | N34: =+CONCATENATE(A34,C34) -> IN01S2203110-00 | O34: 30 | Q34: =+VLOOKUP(N34,Sheet2!A:A,1,) -> IN01S2203110-00
A35: IN | B35: 31 | C35: 01S2401310-00 | D35: =+VLOOKUP(C35,Sheet1!K:M,3,) -> RES-MO-SMD 2K4-1%-0603-100mW-55-155℃-TC100 | F35: 5000 | J35: 5000 | K35: =5000*1 -> 5000 | L35: =+K35-J35 -> 0 | N35: =+CONCATENATE(A35,C35) -> IN01S2401310-00 | O35: 31 | Q35: =+VLOOKUP(N35,Sheet2!A:A,1,) -> IN01S2401310-00
A36: IN | B36: 32 | C36: 01S2402310-00 | D36: =+VLOOKUP(C36,Sheet1!K:M,3,) -> RES-MO-SMD 24K-1%-0603-100mW-55-155℃-TC100 | H36: 15000 | J36: 15000 | K36: =5000*3 -> 15000 | L36: =+K36-J36 -> 0 | N36: =+CONCATENATE(A36,C36) -> IN01S2402310-00 | O36: 32 | Q36: =+VLOOKUP(N36,Sheet2!A:A,1,) -> IN01S2402310-00
A37: IN | B37: 33 | C37: 01S2403110-00 | D37: =+VLOOKUP(C37,Sheet1!K:M,3,) -> RES-MO-SMD 240K-1%-1206-250mW-55-155℃-TC100 | G37: 25000 | J37: 25000 | K37: =5000*5 -> 25000 | L37: =+K37-J37 -> 0 | N37: =+CONCATENATE(A37,C37) -> IN01S2403110-00 | O37: 33 | Q37: =+VLOOKUP(N37,Sheet2!A:A,1,) -> IN01S2403110-00
A38: IN | B38: 34 | C38: 01S2403310-00 | D38: =+VLOOKUP(C38,Sheet1!K:M,3,) -> RES-MO-SMD 240K-1%-0603-100mW-55-155℃-TC100 | H38: 10000 | J38: 10000 | K38: =5000*2 -> 10000 | L38: =+K38-J38 -> 0 | N38: =+CONCATENATE(A38,C38) -> IN01S2403310-00 | O38: 34 | Q38: =+VLOOKUP(N38,Sheet2!A:A,1,) -> IN01S2403310-00
A39: IN | B39: 35 | C39: 01S2404110-00 | D39: =+VLOOKUP(C39,Sheet1!K:M,3,) -> RES-MO-SMD 2M4-1%-1206-250mW-55-155℃-TC100 | G39: 50000 | J39: 50000 | K39: =5000*10 -> 50000 | L39: =+K39-J39 -> 0 | N39: =+CONCATENATE(A39,C39) -> IN01S2404110-00 | O39: 35 | Q39: =+VLOOKUP(N39,Sheet2!A:A,1,) -> IN01S2404110-00
A40: IN | B40: 36 | C40: 01S2702310-00 | D40: =+VLOOKUP(C40,Sheet1!K:M,3,) -> RES-MO-SMD 27K-1%-0603-100mW-55-155℃-TC100 | G40: 10000 | J40: 10000 | K40: =5000*2 -> 10000 | L40: =+K40-J40 -> 0 | N40: =+CONCATENATE(A40,C40) -> IN01S2702310-00 | O40: 36 | Q40: =+VLOOKUP(N40,Sheet2!A:A,1,) -> IN01S2702310-00
A41: IN | B41: 37 | C41: 01S3001310-00 | D41: =+VLOOKUP(C41,Sheet1!K:M,3,) -> RES-MO-SMD 3K-1%-0603-100mW-55-155℃-TC100 | H41: 5000 | J41: 5000 | K41: =5000*1 -> 5000 | L41: =+K41-J41 -> 0 | N41: =+CONCATENATE(A41,C41) -> IN01S3001310-00 | O41: 37 | Q41: =+VLOOKUP(N41,Sheet2!A:A,1,) -> IN01S3001310-00
...

Sheet Sheet1
A1: Transfer Doc. | B1: Transfer Date | C1: Post or Not? | D1: Confirmation | E1: Dept | F1: Employee Name | G1: Applicant | H1: Department Name | I1: Remark | J1: Line No. | K1: Item No. | L1: Item Name | M1: Item Specification | N1: Transfer-out WH | O1: Store Name | P1: Transfer-out Lot | Q1: Transfer-Out Qty (Estimated) | R1: Inventory Unit | S1: Converted Qty | T1: Transfer-in WH | U1: Store Name | V1: Transfer-in Lot | W1: Custom Field - Value | X1: Custom Field - Value | Y1: Custom Field - Text | Z1: Custom Fields - Integer | AA1: Custom Field - Textedit
A2: I1202-25090028 | B2: 25/09/24 | C2: Y | D2: Y | E2: 80007 | F2: Sarvesh Joshi | G2: M000271 | H2: Stores | J2: 1 | K2: 02S1010520-00 | L2: CHIP CAP | M2: CAP-CER-SMD 100P-5%-50V-0603-COG | N2: 3000I | O2: Material Warehouse | P2: 20250819 | Q2: 4000 | R2: PCS | S2: 4000 | T2: 6001I | U2: Kinetic W/H | V2: 20250819 | W2: 0 | X2: 0 | Z2: 0
A3: I1202-25090028 | B3: 25/09/24 | C3: Y | D3: Y | E3: 80007 | F3: Sarvesh Joshi | G3: M000271 | H3: Stores | J3: 2 | K3: 07S4320001-12 | L3: CHIP V-Reg IC | M3: IC-Vol-Reg-SMD LA432OCRPA-125℃-SOT23-3L | N3: 3000I | O3: Material Warehouse | P3: 20250919 | Q3: 15000 | R3: PCS | S3: 15000 | T3: 6001I | U3: Kinetic W/H | V3: 20250919 | W3: 0 | X3: 0 | Z3: 0
A4: I1202-25090028 | B4: 25/09/24 | C4: Y | D4: Y | E4: 80007 | F4: Sarvesh Joshi | G4: M000271 | H4: Stores | J4: 3 | K4: 02S1021501-37 | L4: CHIP Y1-CAP(TMY1102M-Y) | M4: CAP-CER-Y1-SMD 1N-20%-400V-Y5U-7.8*5.4*2.45 | N4: 3000I | O4: Material Warehouse | P4: 20250603 | Q4: 3000 | R4: PCS | S4: 3000 | T4: 6001I | U4: Kinetic W/H | V4: 20250603 | W4: 0 | X4: 0 | Z4: 0
A5: I1202-25090028 | B5: 25/09/24 | C5: Y | D5: Y | E5: 80007 | F5: Sarvesh Joshi | G5: M000271 | H5: Stores | J5: 4 | K5: 13M0700040-00 | L5: Main PCB(EDC-075SXXXSVA REV:A) | M5: 279*218*1.6 FR-4 1/2 12PP Mirror copy board 83.15%-4 | N5: 3000I | O5: Material Warehouse | P5: 20250919 | Q5: 2004 | R5: PCS | S5: 2004 | T5: 6001I | U5: Kinetic W/H | V5: 20250919 | W5: 0 | X5: 0 | Z5: 0
A6: I1202-25090028 | B6: 25/09/24 | C6: Y | D6: Y | E6: 80007 | F6: Sarvesh Joshi | G6: M000271 | H6: Stores | J6: 5 | K6: 01S0000K21-00 | L6: CHIP RES | M6: RES-MO-SMD 0R-5%-0402-63mW-55-155℃-TC400 | N6: 3000I | O6: Material Warehouse | P6: 20250919 | Q6: 20000 | R6: PCS | S6: 20000 | T6: 6001I | U6: Kinetic W/H | V6: 20250919 | W6: 0 | X6: 0 | Z6: 0
A7: I1202-25090028 | B7: 25/09/24 | C7: Y | D7: Y | E7: 80007 | F7: Sarvesh Joshi | G7: M000271 | H7: Stores | J7: 6 | K7: 06S6955001-05 | L7: CHIP N-MOS-(STD6N95K5) | M7: SEM-N-MOS-SMD 950V-9A-1R25-150℃-TO-252(DPAK) | N7: 3000I | O7: Material Warehouse | P7: 20250901 | Q7: 2500 | R7: PCS | S7: 2500 | T7: 6001I | U7: Kinetic W/H | V7: 20250901 | W7: 0 | X7: 0 | Z7: 0
A8: I1202-25090028 | B8: 25/09/24 | C8: Y | D8: Y | E8: 80007 | F8: Sarvesh Joshi | G8: M000271 | H8: Stores | J8: 7 | K8: 04S6010001-16 | L8: CHIP Gas Discharge Tube-(S30-A600XS) | M8: RES-GDT-SMD 1KA-600V-25%-4.5*3.2*2.7 | N8: 3000I | O8: Material Warehouse | P8: 20250901 | Q8: 10000 | R8: PCS | S8: 10000 | T8: 6001I | U8: Kinetic W/H | V8: 20250901 | W8: 0 | X8: 0 | Z8: 0
A9: I1202-25090028 | B9: 25/09/24 | C9: Y | D9: Y | E9: 80007 | F9: Sarvesh Joshi | G9: M000271 | H9: Stores | J9: 9 | K9: 02S1021990-00 | L9: CHIP CAP | M9: CAP-CER-SMD 1N-10%-630V-1206-X7R | N9: 3000I | O9: Material Warehouse | P9: 20250819 | Q9: 3000 | R9: PCS | S9: 3000 | T9: 6001I | U9: Kinetic W/H | V9: 20250819 | W9: 0 | X9: 0 | Z9: 0
A10: I1202-25090028 | B10: 25/09/24 | C10: Y | D10: Y | E10: 80007 | F10: Sarvesh Joshi | G10: M000271 | H10: Stores | J10: 10 | K10: 01S1003311-13 | L10: CHIP Thermistor RES | M10: RES-NTC-SMD 100K-1%-84V-4050K-2.5A-0603 | N10: 3000I | O10: Material Warehouse | P10: 20250919 | Q10: 8000 | R10: PCS | S10: 8000 | T10: 6001I | U10: Kinetic W/H | V10: 20250919 | W10: 0 | X10: 0 | Z10: 0
A11: I1202-25090028 | B11: 25/09/24 | C11: Y | D11: Y | E11: 80007 | F11: Sarvesh Joshi | G11: M000271 | H11: Stores | J11: 11 | K11: 02S4710521-00 | L11: CHIP CAP | M11: CAP-CER-SMD 470P-5%-50V-0603-COG | N11: 3000I | O11: Material Warehouse | P11: 20250919 | Q11: 4000 | R11: PCS | S11: 4000 | T11: 6001I | U11: Kinetic W/H | V11: 20250919 | W11: 0 | X11: 0 | Z11: 0
A12: I1202-25090028 | B12: 25/09/24 | C12: Y | D12: Y | E12: 80007 | F12: Sarvesh Joshi | G12: M000271 | H12: Stores | J12: 12 | K12: 01S1002310-00 | L12: CHIP RES | M12: RES-MO-SMD 10K-1%-0603-100mW-55-155℃-TC100 | N12: 3000I | O12: Material Warehouse | P12: 20250819 | Q12: 30000 | R12: PCS | S12: 30000 | T12: 6001I | U12: Kinetic W/H | V12: 20250819 | W12: 0 | X12: 0 | Z12: 0
A13: I1202-25090028 | B13: 25/09/24 | C13: Y | D13: Y | E13: 80007 | F13: Sarvesh Joshi | G13: M000271 | H13: Stores | J13: 13 | K13: 02S1030530-00 | L13: CHIP CAP | M13: CAP-CER-SMD 10N-10%-50V-0603-X7R | N13: 3000I | O13: Material Warehouse | P13: 20250819 | Q13: 20000 | R13: PCS | S13: 20000 | T13: 6001I | U13: Kinetic W/H | V13: 20250819 | W13: 0 | X13: 0 | Z13: 0
... A125: I1202-25090031 | B125: 25/09/24 | C125: Y | D125: Y | E125: 80007 | F125: Sarvesh Joshi | G125: M000271 | H125: Stores | J125: 43 | K125: 13M1500076-00 | L125: Main PCB(EDC-150SXXXSV REV:A) | M125: 279*170*1.6 FR-4 1/2 6PP Mirror copy board 83.73%-6 | N125: 3000I | O125: Material Warehouse | P125: 20250919 | Q125: 2538 | R125: PCS | S125: 2538 | T125: 6001I | U125: Kinetic W/H | V125: 20250919 | W125: 0 | X125: 0 | Z125: 0

Sheet Sheet2
A1: Item Cd
A2: 01S1500110-00
A3: 01S5603210-00
A4: 086PCB001
A5: 0906-061DM001A0Y
A6: 0906E-706CS002A0Y
A7: 7646C-706S009A0Y
A8: 7646S-158TS001A0Y
A9: 7646T-057S001A0Y
A10: 7646T-057S003AOY
A11: 7646T-061ZMM002A0Y
A12: 7646T-061ZMM004A0Y
... A2208: Z114-091A0Y
